[2022-06-15 17:51:13,950] {taskinstance.py:1043} INFO - Dependencies all met for <TaskInstance: ETL_script.extract_data scheduled__2022-05-08T00:00:00+00:00 [queued]>
[2022-06-15 17:51:13,962] {taskinstance.py:1043} INFO - Dependencies all met for <TaskInstance: ETL_script.extract_data scheduled__2022-05-08T00:00:00+00:00 [queued]>
[2022-06-15 17:51:13,963] {taskinstance.py:1249} INFO - 
--------------------------------------------------------------------------------
[2022-06-15 17:51:13,963] {taskinstance.py:1250} INFO - Starting attempt 2 of 2
[2022-06-15 17:51:13,964] {taskinstance.py:1251} INFO - 
--------------------------------------------------------------------------------
[2022-06-15 17:51:13,979] {taskinstance.py:1270} INFO - Executing <Task(BashOperator): extract_data> on 2022-05-08 00:00:00+00:00
[2022-06-15 17:51:13,982] {standard_task_runner.py:52} INFO - Started process 118 to run task
[2022-06-15 17:51:13,989] {standard_task_runner.py:79} INFO - Running: ['***', 'tasks', 'run', 'ETL_script', 'extract_data', 'scheduled__2022-05-08T00:00:00+00:00', '--job-id', '147', '--raw', '--subdir', 'DAGS_FOLDER/ETL_script.py', '--cfg-path', '/tmp/tmpgzv5v52i', '--error-file', '/tmp/tmpgbhjfal7']
[2022-06-15 17:51:13,991] {standard_task_runner.py:80} INFO - Job 147: Subtask extract_data
[2022-06-15 17:51:14,065] {logging_mixin.py:109} INFO - Running <TaskInstance: ETL_script.extract_data scheduled__2022-05-08T00:00:00+00:00 [running]> on host 4c9d01f48299
[2022-06-15 17:51:14,151] {taskinstance.py:1448} INFO - Exporting the following env vars:
AIRFLOW_CTX_DAG_EMAIL=***@***.com
AIRFLOW_CTX_DAG_OWNER=***
AIRFLOW_CTX_DAG_ID=ETL_script
AIRFLOW_CTX_TASK_ID=extract_data
AIRFLOW_CTX_EXECUTION_DATE=2022-05-08T00:00:00+00:00
AIRFLOW_CTX_DAG_RUN_ID=scheduled__2022-05-08T00:00:00+00:00
[2022-06-15 17:51:14,154] {subprocess.py:62} INFO - Tmp dir root location: 
 /tmp
[2022-06-15 17:51:14,155] {subprocess.py:74} INFO - Running command: ['bash', '-c', '/Users/hamza.ahmed/Coding Projects/Python_Apps/Docker_Applications/Airflow_Docker_Apps/Python_Scripts/API_extract.py']
[2022-06-15 17:51:14,167] {subprocess.py:85} INFO - Output:
[2022-06-15 17:51:14,170] {subprocess.py:89} INFO - bash: /Users/hamza.ahmed/Coding: No such file or directory
[2022-06-15 17:51:14,171] {subprocess.py:93} INFO - Command exited with return code 127
[2022-06-15 17:51:14,191] {taskinstance.py:1774} ERROR - Task failed with exception
Traceback (most recent call last):
  File "/home/airflow/.local/lib/python3.7/site-packages/airflow/operators/bash.py", line 188, in execute
    f'Bash command failed. The command returned a non-zero exit code {result.exit_code}.'
airflow.exceptions.AirflowException: Bash command failed. The command returned a non-zero exit code 127.
[2022-06-15 17:51:14,199] {taskinstance.py:1288} INFO - Marking task as FAILED. dag_id=ETL_script, task_id=extract_data, execution_date=20220508T000000, start_date=20220615T175113, end_date=20220615T175114
[2022-06-15 17:51:14,218] {warnings.py:110} WARNING - /home/***/.local/lib/python3.7/site-packages/***/utils/email.py:108: PendingDeprecationWarning: Fetching SMTP credentials from configuration variables will be deprecated in a future release. Please set credentials using a connection instead.
  send_mime_email(e_from=mail_from, e_to=recipients, mime_msg=msg, conn_id=conn_id, dryrun=dryrun)

[2022-06-15 17:51:14,219] {configuration.py:381} WARNING - section/key [smtp/smtp_user] not found in config
[2022-06-15 17:51:14,219] {email.py:214} INFO - Email alerting: attempt 1
[2022-06-15 17:51:14,229] {configuration.py:381} WARNING - section/key [smtp/smtp_user] not found in config
[2022-06-15 17:51:14,231] {email.py:214} INFO - Email alerting: attempt 1
[2022-06-15 17:51:14,232] {taskinstance.py:1825} ERROR - Failed to send email to: ['***@***.com']
Traceback (most recent call last):
  File "/home/airflow/.local/lib/python3.7/site-packages/airflow/models/taskinstance.py", line 1340, in _run_raw_task
    self._execute_task_with_callbacks(context)
  File "/home/airflow/.local/lib/python3.7/site-packages/airflow/models/taskinstance.py", line 1477, in _execute_task_with_callbacks
    result = self._execute_task(context, self.task)
  File "/home/airflow/.local/lib/python3.7/site-packages/airflow/models/taskinstance.py", line 1538, in _execute_task
    result = execute_callable(context=context)
  File "/home/airflow/.local/lib/python3.7/site-packages/airflow/operators/bash.py", line 188, in execute
    f'Bash command failed. The command returned a non-zero exit code {result.exit_code}.'
airflow.exceptions.AirflowException: Bash command failed. The command returned a non-zero exit code 127.

During handling of the above exception, another exception occurred:

Traceback (most recent call last):
  File "/home/airflow/.local/lib/python3.7/site-packages/airflow/models/taskinstance.py", line 2159, in email_alert
    send_email(self.task.email, subject, html_content)
  File "/home/airflow/.local/lib/python3.7/site-packages/airflow/utils/email.py", line 69, in send_email
    **kwargs,
  File "/home/airflow/.local/lib/python3.7/site-packages/airflow/utils/email.py", line 108, in send_email_smtp
    send_mime_email(e_from=mail_from, e_to=recipients, mime_msg=msg, conn_id=conn_id, dryrun=dryrun)
  File "/home/airflow/.local/lib/python3.7/site-packages/airflow/utils/email.py", line 216, in send_mime_email
    conn = _get_smtp_connection(smtp_host, smtp_port, smtp_timeout, smtp_ssl)
  File "/home/airflow/.local/lib/python3.7/site-packages/airflow/utils/email.py", line 250, in _get_smtp_connection
    else smtplib.SMTP(host=host, port=port, timeout=timeout)
  File "/usr/local/lib/python3.7/smtplib.py", line 251, in __init__
    (code, msg) = self.connect(host, port)
  File "/usr/local/lib/python3.7/smtplib.py", line 336, in connect
    self.sock = self._get_socket(host, port, self.timeout)
  File "/usr/local/lib/python3.7/smtplib.py", line 307, in _get_socket
    self.source_address)
  File "/usr/local/lib/python3.7/socket.py", line 728, in create_connection
    raise err
  File "/usr/local/lib/python3.7/socket.py", line 716, in create_connection
    sock.connect(sa)
OSError: [Errno 99] Cannot assign requested address

During handling of the above exception, another exception occurred:

Traceback (most recent call last):
  File "/home/airflow/.local/lib/python3.7/site-packages/airflow/models/taskinstance.py", line 1823, in handle_failure
    self.email_alert(error)
  File "/home/airflow/.local/lib/python3.7/site-packages/airflow/models/taskinstance.py", line 2161, in email_alert
    send_email(self.task.email, subject, html_content_err)
  File "/home/airflow/.local/lib/python3.7/site-packages/airflow/utils/email.py", line 69, in send_email
    **kwargs,
  File "/home/airflow/.local/lib/python3.7/site-packages/airflow/utils/email.py", line 108, in send_email_smtp
    send_mime_email(e_from=mail_from, e_to=recipients, mime_msg=msg, conn_id=conn_id, dryrun=dryrun)
  File "/home/airflow/.local/lib/python3.7/site-packages/airflow/utils/email.py", line 216, in send_mime_email
    conn = _get_smtp_connection(smtp_host, smtp_port, smtp_timeout, smtp_ssl)
  File "/home/airflow/.local/lib/python3.7/site-packages/airflow/utils/email.py", line 250, in _get_smtp_connection
    else smtplib.SMTP(host=host, port=port, timeout=timeout)
  File "/usr/local/lib/python3.7/smtplib.py", line 251, in __init__
    (code, msg) = self.connect(host, port)
  File "/usr/local/lib/python3.7/smtplib.py", line 336, in connect
    self.sock = self._get_socket(host, port, self.timeout)
  File "/usr/local/lib/python3.7/smtplib.py", line 307, in _get_socket
    self.source_address)
  File "/usr/local/lib/python3.7/socket.py", line 728, in create_connection
    raise err
  File "/usr/local/lib/python3.7/socket.py", line 716, in create_connection
    sock.connect(sa)
OSError: [Errno 99] Cannot assign requested address
[2022-06-15 17:51:14,263] {standard_task_runner.py:98} ERROR - Failed to execute job 147 for task extract_data (Bash command failed. The command returned a non-zero exit code 127.; 118)
[2022-06-15 17:51:14,284] {local_task_job.py:154} INFO - Task exited with return code 1
[2022-06-15 17:51:14,339] {local_task_job.py:264} INFO - 0 downstream tasks scheduled from follow-on schedule check
